Workbook

Sheet 📋 SOP
B2: 📊 E-COMMERCE P&L TRACKER — STANDARD OPERATING PROCEDURE
B4: Version 1.0 · Baseline Year: 2026 · For use by: Blueprint Academy
B7: 1. PURPOSE & OVERVIEW
B8: This tracker is a daily Profit & Loss tool built for e-commerce store owners. It records revenue, refunds, advertising spend, agency fees, cost of goods, and transaction fees on a daily basis — and automatically calculates net profit, profit margin, ROAS, and cumulative profit for each month. An annual Dashboard consolidates all 12 months into a single view.
B10: 2. WORKBOOK STRUCTURE
B11: TAB 1 | C11: 📋 SOP | D11: This document. Read before using the tracker.
B12: TAB 2 | C12: ⚙ Settings | D12: Set your currency (€ / $ / £), baseline year, and default fee percentages here. Do this FIRST before entering any data.
B13: TAB 3 | C13: 📊 Dashboard | D13: Annual summary with KPIs and monthly breakdown. Read-only — all values pull automatically from the monthly sheets.
B14: TAB 4–15 | C14: January → December | D14: One tab per month. Enter your daily data here. Each sheet covers all days of that month.
B17: 3. FIRST-TIME SETUP (do this once)
B18: Step 1 | C18: Open the ⚙ Settings tab | D18: Navigate to the Settings tab (second tab in the workbook).
B19: Step 2 | C19: Select your currency | D19: Click cell C6 and choose your currency from the dropdown: € (EUR), $ (USD), or £ (GBP). The symbol will appear in all sheet headers automatically.
B20: Step 3 | C20: Confirm the year | D20: Cell C10 shows the baseline year (2026). If you are starting a new year, duplicate the entire file and update this cell.
B21: Step 4 | C21: Set default fee percentages | D21: In cells C14, C15, and C16 set your Agency Fee (Facebook), Agency Fee (Google), and Transaction Fee defaults. These are pre-filled in each monthly sheet but can be overridden per month.
B22: Step 5 | C22: You're ready to enter data | D22: Navigate to the month tab you want to start with and begin entering daily figures.
B23: ⚠️ Important: Complete the Settings tab before entering any data to ensure formulas reference the correct values.
B26: 4. DAILY DATA ENTRY (do this every day)
B27: In each monthly sheet, only the BLUE-highlighted columns require manual input. All other columns calculate automatically.
B28: Col A | C28: Date | D28: Pre-filled automatically. Do not edit.
B29: Col B | C29: Gross Revenue | D29: Enter the total revenue generated that day BEFORE deducting refunds. Include all sales channels.
B30: Col C | C30: Refunds | D30: Enter the total value of refunds/returns processed that day.
B31: Col D | C31: Net Revenue | D31: AUTO: Gross Revenue minus Refunds.
B32: Col E | C32: Cost of Goods (COGS) | D32: Enter the total cost of products sold that day (purchase price, manufacturing, fulfilment).
B33: Col F | C33: Adspend — Facebook | D33: Enter the total Facebook/Meta advertising spend for that day.
B34: Col G | C34: Adspend — Google | D34: Enter the total Google Ads advertising spend for that day.
B35: Col H | C35: Agency Fee — Facebook | D35: AUTO: Calculated as Adspend FB × Agency Fee FB %. Override the % in row 4.
B36: Col I | C36: Agency Fee — Google | D36: AUTO: Calculated as Adspend Google × Agency Fee Google %. Override the % in row 4.
B37: Col J | C37: Transaction Fee | D37: AUTO: Calculated as Gross Revenue × Transaction Fee %. Override the % in row 4.
B38: Col K | C38: Total Costs | D38: AUTO: Sum of COGS + Adspend FB + Adspend Google + Agency Fees + Transaction Fee.
B39: Col L | C39: Profit | D39: AUTO: Net Revenue minus Total Costs. Green = positive, Red = negative.
... B44: Col Q | C44: Notes | D44: Free text. Use this to log campaign names, promotions, anomalies, or any day-specific context.
B47: 5. OVERRIDING FEES PER MONTH
B48: Row 4 | C48: Fee Labels | D48: Rows 3–4 of each monthly sheet display the three fee assumptions.
B49: Edit | C49: Change a % | D49: Click the yellow cell in row 4 (Agency Fee FB, Agency Fee Google, or Transaction Fee) and type a new percentage. All rows in that month will recalculate instantly.
B50: 💡 Each month has its own independent fee settings. Changing January's fees does not affect February.
B53: 6. COLOUR CODING GUIDE
B54: ● | C54: 🔵 Blue background | D54: Manual input cells — these are the only cells you should type into.
B55: ● | C55: ⬜ White/Grey bg | D55: Auto-calculated cells — do not edit. These update when you change blue cells.
B56: ● | C56: 🟡 Yellow background | D56: Assumption cells (fee percentages) — editable. Changes cascade to all rows.
B57: ● | C57: 🟢 Green cell | D57: Profit or Margin is positive and above 15%. Healthy performance.
...

Sheet ⚙ Settings
B2: ⚙️ Global Settings — E-Commerce P&L Tracker
B5: CURRENCY SETTINGS
B6: Currency Symbol | C6: €
B7: Choose your currency from the dropdown above (C6). All monthly sheets will display the selected symbol.
B9: YEAR SETTINGS
B10: Baseline Year | C10: 2026
B11: To use this tracker for a new year: duplicate the entire file and update the year above.
B13: DEFAULT FEE ASSUMPTIONS (applied as defaults in each monthly sheet — you can override per month)
B14: Agency Fee — Facebook | C14: 0.06 | D14: Editable — change this to update the default for all sheets
B15: Agency Fee — Google | C15: 0.1 | D15: Editable — change this to update the default for all sheets
B16: Transaction Fee | C16: 0.05 | D16: Editable — change this to update the default for all sheets

Sheet 📊 Dashboard
B2: 📊 E-Commerce P&L Dashboard — 2026 | G2: ="Currency: "&'⚙ Settings'!C6 -> Currency: €
B5: ANNUAL SUMMARY — all values pull automatically from monthly sheets
B7: 💰 Gross Revenue | C7: 💵 Net Revenue | D7: 📈 Total Profit | E7: 📊 Profit Margin | F7: 🎯 ROAS | G7: 📣 Total Adspend
B8: =January!B39+February!B36+March!B39+April!B38+May!B39+June!B38+July!B39+August!B39+September!B38+October!B39+November!B38+December!B39 -> 0 | C8: =January!D39+February!D36+March!D39+April!D38+May!D39+June!D38+July!D39+August!D39+September!D38+October!D39+November!D38+December!D39 -> 0 | D8: =January!L39+February!L36+March!L39+April!L38+May!L39+June!L38+July!L39+August!L39+September!L38+October!L39+November!L38+December!L39 -> 0 | E8: =IF((January!D39+February!D36+March!D39+April!D38+May!D39+June!D38+July!D39+August!D39+September!D38+October!D39+November!D38+December!D39)=0,0,(January!L39+February!L36+March!L39+April!L38+May!L39+June!L38+July!L39+August!L39+September!L38+October!L39+November!L38+December!L39)/(January!D39+February!D36+March!D39+April!D38+May!D39+June!D38+July!D39+August!D39+September!D38+October!D39+November!D38+December!D39)) -> 0 | F8: =IF((January!F39+January!G39+February!F36+February!G36+March!F39+March!G39+April!F38+April!G38+May!F39+May!G39+June!F38+June!G38+July!F39+July!G39+August!F39+August!G39+September!F38+September!G38+October!F39+October!G39+November!F38+November!G38+December!F39+December!G39)=0,"-",(January!D39+February!D36+March!D39+April!D38+May!D39+June!D38+July!D39+August!D39+September!D38+October!D39+November!D38+December!D39)/(January!F39+January!G39+February!F36+February!G36+March!F39+March!G39+April!F38+April!G38+May!F39+May!G39+June!F38+June!G38+July!F39+July!G39+August!F39+August!G39+September!F38+September!G38+October!F39+October!G39+November!F38+November!G38+December!F39+December!G39)) -> - | G8: =January!F39+February!F36+March!F39+April!F38+May!F39+June!F38+July!F39+August!F39+September!F38+October!F39+November!F38+December!F39+January!G39+February!G36+March!G39+April!G38+May!G39+June!G38+July!G39+August!G39+September!G38+October!G39+November!G38+December!G39 -> 0
B11: MONTHLY BREAKDOWN
B12: MONTH | C12: GROSS REVENUE | D12: NET REVENUE | E12: PROFIT | F12: MARGIN % | G12: ROAS
B13: January | C13: =January!B39 -> 0 | D13: =January!D39 -> 0 | E13: =January!L39 -> 0 | F13: =January!M39 -> - | G13: =January!O39 -> -
B14: February | C14: =February!B36 -> 0 | D14: =February!D36 -> 0 | E14: =February!L36 -> 0 | F14: =February!M36 -> - | G14: =February!O36 -> -
B15: March | C15: =March!B39 -> 0 | D15: =March!D39 -> 0 | E15: =March!L39 -> 0 | F15: =March!M39 -> - | G15: =March!O39 -> -
B16: April | C16: =April!B38 -> 0 | D16: =April!D38 -> 0 | E16: =April!L38 -> 0 | F16: =April!M38 -> - | G16: =April!O38 -> -
B17: May | C17: =May!B39 -> 0 | D17: =May!D39 -> 0 | E17: =May!L39 -> 0 | F17: =May!M39 -> - | G17: =May!O39 -> -
B18: June | C18: =June!B38 -> 0 | D18: =June!D38 -> 0 | E18: =June!L38 -> 0 | F18: =June!M38 -> - | G18: =June!O38 -> -
B19: July | C19: =July!B39 -> 0 | D19: =July!D39 -> 0 | E19: =July!L39 -> 0 | F19: =July!M39 -> - | G19: =July!O39 -> -
B20: August | C20: =August!B39 -> 0 | D20: =August!D39 -> 0 | E20: =August!L39 -> 0 | F20: =August!M39 -> - | G20: =August!O39 -> -
B21: September | C21: =September!B38 -> 0 | D21: =September!D38 -> 0 | E21: =September!L38 -> 0 | F21: =September!M38 -> - | G21: =September!O38 -> -
B22: October | C22: =October!B39 -> 0 | D22: =October!D39 -> 0 | E22: =October!L39 -> 0 | F22: =October!M39 -> - | G22: =October!O39 -> -
B23: November | C23: =November!B38 -> 0 | D23: =November!D38 -> 0 | E23: =November!L38 -> 0 | F23: =November!M38 -> - | G23: =November!O38 -> -
B24: December | C24: =December!B39 -> 0 | D24: =December!D39 -> 0 | E24: =December!L39 -> 0 | F24: =December!M39 -> - | G24: =December!O39 -> -
B25: ANNUAL TOTAL | C25: =January!B39+February!B36+March!B39+April!B38+May!B39+June!B38+July!B39+August!B39+September!B38+October!B39+November!B38+December!B39 -> 0 | D25: =January!D39+February!D36+March!D39+April!D38+May!D39+June!D38+July!D39+August!D39+September!D38+October!D39+November!D38+December!D39 -> 0 | E25: =January!L39+February!L36+March!L39+April!L38+May!L39+June!L38+July!L39+August!L39+September!L38+October!L39+November!L38+December!L39 -> 0 | F25: =IF((January!D39+February!D36+March!D39+April!D38+May!D39+June!D38+July!D39+August!D39+September!D38+October!D39+November!D38+December!D39)=0,0,(January!L39+February!L36+March!L39+April!L38+May!L39+June!L38+July!L39+August!L39+September!L38+October!L39+November!L38+December!L39)/(January!D39+February!D36+March!D39+April!D38+May!D39+June!D38+July!D39+August!D39+September!D38+October!D39+November!D38+December!D39)) -> 0 | G25: =IF((January!F39+January!G39+February!F36+February!G36+March!F39+March!G39+April!F38+April!G38+May!F39+May!G39+June!F38+June!G38+July!F39+July!G39+August!F39+August!G39+September!F38+September!G38+October!F39+October!G39+November!F38+November!G38+December!F39+December!G39)=0,"-",(January!D39+February!D36+March!D39+April!D38+May!D39+June!D38+July!D39+August!D39+September!D38+October!D39+November!D38+December!D39)/(January!F39+January!G39+February!F36+February!G36+March!F39+March!G39+April!F38+April!G38+May!F39+May!G39+June!F38+June!G38+July!F39+July!G39+August!F39+August!G39+September!F38+September!G38+October!F39+October!G39+November!F38+November!G38+December!F39+December!G39)) -> -
B27: 💡 To enter data, open the relevant month tab · All values on this dashboard update automatically · See 📋 SOP for full instructions

Sheet January
A2: 📊 Profit & Loss — January 2026 | N2: ="Currency: "&'⚙ Settings'!C6 -> Currency: €
A4: Agency Fee — Facebook | D4: Agency Fee — Google | G4: Transaction Fee | J4: 💡 Edit the coloured % cells above to update all fee calculations for this month automatically
A5: 0.06 | D5: 0.1 | G5: 0.05
A7: Date | B7: Gross Revenue | C7: Refunds | D7: Net Revenue | E7: Cost of Goods | F7: Adspend Facebook | G7: Adspend Google | H7: Agency Fee FB | I7: Agency Fee Google | J7: Transaction Fee | K7: Total Costs | L7: Profit | M7: Profit Margin % | N7: COG Impact % | O7: ROAS | P7: Cumulative Profit | Q7: Notes
A8: 46023 | B8: 1234.56 | C8: 50 | D8: =B8-C8 -> 0 | E8: 0 | F8: 0 | G8: 0 | H8: =F8*$A$5 -> 0 | I8: =G8*$D$5 -> 0 | J8: =B8*$G$5 -> 0 | K8: =E8+F8+G8+H8+I8+J8 -> 0 | L8: =D8-K8 -> 0 | M8: =IF(D8=0,"-",L8/D8) -> - | N8: =IF(D8=0,"-",E8/D8) -> - | O8: =IF((F8+G8)=0,"-",D8/(F8+G8)) -> - | P8: =L8 -> 0
A9: 46024 | B9: 0 | C9: 0 | D9: =B9-C9 -> 0 | E9: 0 | F9: 0 | G9: 0 | H9: =F9*$A$5 -> 0 | I9: =G9*$D$5 -> 0 | J9: =B9*$G$5 -> 0 | K9: =E9+F9+G9+H9+I9+J9 -> 0 | L9: =D9-K9 -> 0 | M9: =IF(D9=0,"-",L9/D9) -> - | N9: =IF(D9=0,"-",E9/D9) -> - | O9: =IF((F9+G9)=0,"-",D9/(F9+G9)) -> - | P9: =P8+L9 -> 0
A10: 46025 | B10: 0 | C10: 0 | D10: =B10-C10 -> 0 | E10: 0 | F10: 0 | G10: 0 | H10: =F10*$A$5 -> 0 | I10: =G10*$D$5 -> 0 | J10: =B10*$G$5 -> 0 | K10: =E10+F10+G10+H10+I10+J10 -> 0 | L10: =D10-K10 -> 0 | M10: =IF(D10=0,"-",L10/D10) -> - | N10: =IF(D10=0,"-",E10/D10) -> - | O10: =IF((F10+G10)=0,"-",D10/(F10+G10)) -> - | P10: =P9+L10 -> 0
A11: 46026 | B11: 0 | C11: 0 | D11: =B11-C11 -> 0 | E11: 0 | F11: 0 | G11: 0 | H11: =F11*$A$5 -> 0 | I11: =G11*$D$5 -> 0 | J11: =B11*$G$5 -> 0 | K11: =E11+F11+G11+H11+I11+J11 -> 0 | L11: =D11-K11 -> 0 | M11: =IF(D11=0,"-",L11/D11) -> - | N11: =IF(D11=0,"-",E11/D11) -> - | O11: =IF((F11+G11)=0,"-",D11/(F11+G11)) -> - | P11: =P10+L11 -> 0
A12: 46027 | B12: 0 | C12: 0 | D12: =B12-C12 -> 0 | E12: 0 | F12: 0 | G12: 0 | H12: =F12*$A$5 -> 0 | I12: =G12*$D$5 -> 0 | J12: =B12*$G$5 -> 0 | K12: =E12+F12+G12+H12+I12+J12 -> 0 | L12: =D12-K12 -> 0 | M12: =IF(D12=0,"-",L12/D12) -> - | N12: =IF(D12=0,"-",E12/D12) -> - | O12: =IF((F12+G12)=0,"-",D12/(F12+G12)) -> - | P12: =P11+L12 -> 0
A13: 46028 | B13: 0 | C13: 0 | D13: =B13-C13 -> 0 | E13: 0 | F13: 0 | G13: 0 | H13: =F13*$A$5 -> 0 | I13: =G13*$D$5 -> 0 | J13: =B13*$G$5 -> 0 | K13: =E13+F13+G13+H13+I13+J13 -> 0 | L13: =D13-K13 -> 0 | M13: =IF(D13=0,"-",L13/D13) -> - | N13: =IF(D13=0,"-",E13/D13) -> - | O13: =IF((F13+G13)=0,"-",D13/(F13+G13)) -> - | P13: =P12+L13 -> 0
A14: 46029 | B14: 0 | C14: 0 | D14: =B14-C14 -> 0 | E14: 0 | F14: 0 | G14: 0 | H14: =F14*$A$5 -> 0 | I14: =G14*$D$5 -> 0 | J14: =B14*$G$5 -> 0 | K14: =E14+F14+G14+H14+I14+J14 -> 0 | L14: =D14-K14 -> 0 | M14: =IF(D14=0,"-",L14/D14) -> - | N14: =IF(D14=0,"-",E14/D14) -> - | O14: =IF((F14+G14)=0,"-",D14/(F14+G14)) -> - | P14: =P13+L14 -> 0
A15: 46030 | B15: 0 | C15: 0 | D15: =B15-C15 -> 0 | E15: 0 | F15: 0 | G15: 0 | H15: =F15*$A$5 -> 0 | I15: =G15*$D$5 -> 0 | J15: =B15*$G$5 -> 0 | K15: =E15+F15+G15+H15+I15+J15 -> 0 | L15: =D15-K15 -> 0 | M15: =IF(D15=0,"-",L15/D15) -> - | N15: =IF(D15=0,"-",E15/D15) -> - | O15: =IF((F15+G15)=0,"-",D15/(F15+G15)) -> - | P15: =P14+L15 -> 0
A16: 46031 | B16: 0 | C16: 0 | D16: =B16-C16 -> 0 | E16: 0 | F16: 0 | G16: 0 | H16: =F16*$A$5 -> 0 | I16: =G16*$D$5 -> 0 | J16: =B16*$G$5 -> 0 | K16: =E16+F16+G16+H16+I16+J16 -> 0 | L16: =D16-K16 -> 0 | M16: =IF(D16=0,"-",L16/D16) -> - | N16: =IF(D16=0,"-",E16/D16) -> - | O16: =IF((F16+G16)=0,"-",D16/(F16+G16)) -> - | P16: =P15+L16 -> 0
A17: 46032 | B17: 0 | C17: 0 | D17: =B17-C17 -> 0 | E17: 0 | F17: 0 | G17: 0 | H17: =F17*$A$5 -> 0 | I17: =G17*$D$5 -> 0 | J17: =B17*$G$5 -> 0 | K17: =E17+F17+G17+H17+I17+J17 -> 0 | L17: =D17-K17 -> 0 | M17: =IF(D17=0,"-",L17/D17) -> - | N17: =IF(D17=0,"-",E17/D17) -> - | O17: =IF((F17+G17)=0,"-",D17/(F17+G17)) -> - | P17: =P16+L17 -> 0
A18: 46033 | B18: 0 | C18: 0 | D18: =B18-C18 -> 0 | E18: 0 | F18: 0 | G18: 0 | H18: =F18*$A$5 -> 0 | I18: =G18*$D$5 -> 0 | J18: =B18*$G$5 -> 0 | K18: =E18+F18+G18+H18+I18+J18 -> 0 | L18: =D18-K18 -> 0 | M18: =IF(D18=0,"-",L18/D18) -> - | N18: =IF(D18=0,"-",E18/D18) -> - | O18: =IF((F18+G18)=0,"-",D18/(F18+G18)) -> - | P18: =P17+L18 -> 0
A19: 46034 | B19: 0 | C19: 0 | D19: =B19-C19 -> 0 | E19: 0 | F19: 0 | G19: 0 | H19: =F19*$A$5 -> 0 | I19: =G19*$D$5 -> 0 | J19: =B19*$G$5 -> 0 | K19: =E19+F19+G19+H19+I19+J19 -> 0 | L19: =D19-K19 -> 0 | M19: =IF(D19=0,"-",L19/D19) -> - | N19: =IF(D19=0,"-",E19/D19) -> - | O19: =IF((F19+G19)=0,"-",D19/(F19+G19)) -> - | P19: =P18+L19 -> 0
A20: 46035 | B20: 0 | C20: 0 | D20: =B20-C20 -> 0 | E20: 0 | F20: 0 | G20: 0 | H20: =F20*$A$5 -> 0 | I20: =G20*$D$5 -> 0 | J20: =B20*$G$5 -> 0 | K20: =E20+F20+G20+H20+I20+J20 -> 0 | L20: =D20-K20 -> 0 | M20: =IF(D20=0,"-",L20/D20) -> - | N20: =IF(D20=0,"-",E20/D20) -> - | O20: =IF((F20+G20)=0,"-",D20/(F20+G20)) -> - | P20: =P19+L20 -> 0
... A38: 46053 | B38: 0 | C38: 0 | D38: =B38-C38 -> 0 | E38: 0 | F38: 0 | G38: 0 | H38: =F38*$A$5 -> 0 | I38: =G38*$D$5 -> 0 | J38: =B38*$G$5 -> 0 | K38: =E38+F38+G38+H38+I38+J38 -> 0 | L38: =D38-K38 -> 0 | M38: =IF(D38=0,"-",L38/D38) -> - | N38: =IF(D38=0,"-",E38/D38) -> - | O38: =IF((F38+G38)=0,"-",D38/(F38+G38)) -> - | P38: =P37+L38 -> 0
A39: TOTAL | B39: =SUM(B8:B38) -> 0 | C39: =SUM(C8:C38) -> 0 | D39: =SUM(D8:D38) -> 0 | E39: =SUM(E8:E38) -> 0 | F39: =SUM(F8:F38) -> 0 | G39: =SUM(G8:G38) -> 0 | H39: =SUM(H8:H38) -> 0 | I39: =SUM(I8:I38) -> 0 | ... L39: =SUM(L8:L38) -> 0 | M39: =IF(D39=0,"-",L39/D39) -> - | N39: =IF(D39=0,"-",E39/D39) -> - | O39: =IF((F39+G39)=0,"-",D39/(F39+G39)) -> - | P39: =L39 -> 0
A41: 🔵 Blue = enter manually | ⬜ White/Grey = auto-calculated | 🟡 Yellow = editable fee % | 🟢 Green = positive | 🟡 Amber = 0–15% margin | 🔴 Red = negative

Sheet February
A2: 📊 Profit & Loss — February 2026 | N2: ="Currency: "&'⚙ Settings'!C6 -> Currency: €
A4: Agency Fee — Facebook | D4: Agency Fee — Google | G4: Transaction Fee | J4: 💡 Edit the coloured % cells above to update all fee calculations for this month automatically
A5: 0.06 | D5: 0.1 | G5: 0.05
A7: Date | B7: Gross Revenue | C7: Refunds | D7: Net Revenue | E7: Cost of Goods | F7: Adspend Facebook | G7: Adspend Google | H7: Agency Fee FB | I7: Agency Fee Google | J7: Transaction Fee | K7: Total Costs | L7: Profit | M7: Profit Margin % | N7: COG Impact % | O7: ROAS | P7: Cumulative Profit | Q7: Notes
A8: 46054 | B8: 0 | C8: 0 | D8: =B8-C8 -> 0 | E8: 0 | F8: 0 | G8: 0 | H8: =F8*$A$5 -> 0 | I8: =G8*$D$5 -> 0 | J8: =B8*$G$5 -> 0 | K8: =E8+F8+G8+H8+I8+J8 -> 0 | L8: =D8-K8 -> 0 | M8: =IF(D8=0,"-",L8/D8) -> - | N8: =IF(D8=0,"-",E8/D8) -> - | O8: =IF((F8+G8)=0,"-",D8/(F8+G8)) -> - | P8: =L8 -> 0
A9: 46055 | B9: 0 | C9: 0 | D9: =B9-C9 -> 0 | E9: 0 | F9: 0 | G9: 0 | H9: =F9*$A$5 -> 0 | I9: =G9*$D$5 -> 0 | J9: =B9*$G$5 -> 0 | K9: =E9+F9+G9+H9+I9+J9 -> 0 | L9: =D9-K9 -> 0 | M9: =IF(D9=0,"-",L9/D9) -> - | N9: =IF(D9=0,"-",E9/D9) -> - | O9: =IF((F9+G9)=0,"-",D9/(F9+G9)) -> - | P9: =P8+L9 -> 0
A10: 46056 | B10: 0 | C10: 0 | D10: =B10-C10 -> 0 | E10: 0 | F10: 0 | G10: 0 | H10: =F10*$A$5 -> 0 | I10: =G10*$D$5 -> 0 | J10: =B10*$G$5 -> 0 | K10: =E10+F10+G10+H10+I10+J10 -> 0 | L10: =D10-K10 -> 0 | M10: =IF(D10=0,"-",L10/D10) -> - | N10: =IF(D10=0,"-",E10/D10) -> - | O10: =IF((F10+G10)=0,"-",D10/(F10+G10)) -> - | P10: =P9+L10 -> 0
A11: 46057 | B11: 0 | C11: 0 | D11: =B11-C11 -> 0 | E11: 0 | F11: 0 | G11: 0 | H11: =F11*$A$5 -> 0 | I11: =G11*$D$5 -> 0 | J11: =B11*$G$5 -> 0 | K11: =E11+F11+G11+H11+I11+J11 -> 0 | L11: =D11-K11 -> 0 | M11: =IF(D11=0,"-",L11/D11) -> - | N11: =IF(D11=0,"-",E11/D11) -> - | O11: =IF((F11+G11)=0,"-",D11/(F11+G11)) -> - | P11: =P10+L11 -> 0
A12: 46058 | B12: 0 | C12: 0 | D12: =B12-C12 -> 0 | E12: 0 | F12: 0 | G12: 0 | H12: =F12*$A$5 -> 0 | I12: =G12*$D$5 -> 0 | J12: =B12*$G$5 -> 0 | K12: =E12+F12+G12+H12+I12+J12 -> 0 | L12: =D12-K12 -> 0 | M12: =IF(D12=0,"-",L12/D12) -> - | N12: =IF(D12=0,"-",E12/D12) -> - | O12: =IF((F12+G12)=0,"-",D12/(F12+G12)) -> - | P12: =P11+L12 -> 0
A13: 46059 | B13: 0 | C13: 0 | D13: =B13-C13 -> 0 | E13: 0 | F13: 0 | G13: 0 | H13: =F13*$A$5 -> 0 | I13: =G13*$D$5 -> 0 | J13: =B13*$G$5 -> 0 | K13: =E13+F13+G13+H13+I13+J13 -> 0 | L13: =D13-K13 -> 0 | M13: =IF(D13=0,"-",L13/D13) -> - | N13: =IF(D13=0,"-",E13/D13) -> - | O13: =IF((F13+G13)=0,"-",D13/(F13+G13)) -> - | P13: =P12+L13 -> 0
A14: 46060 | B14: 0 | C14: 0 | D14: =B14-C14 -> 0 | E14: 0 | F14: 0 | G14: 0 | H14: =F14*$A$5 -> 0 | I14: =G14*$D$5 -> 0 | J14: =B14*$G$5 -> 0 | K14: =E14+F14+G14+H14+I14+J14 -> 0 | L14: =D14-K14 -> 0 | M14: =IF(D14=0,"-",L14/D14) -> - | N14: =IF(D14=0,"-",E14/D14) -> - | O14: =IF((F14+G14)=0,"-",D14/(F14+G14)) -> - | P14: =P13+L14 -> 0
A15: 46061 | B15: 0 | C15: 0 | D15: =B15-C15 -> 0 | E15: 0 | F15: 0 | G15: 0 | H15: =F15*$A$5 -> 0 | I15: =G15*$D$5 -> 0 | J15: =B15*$G$5 -> 0 | K15: =E15+F15+G15+H15+I15+J15 -> 0 | L15: =D15-K15 -> 0 | M15: =IF(D15=0,"-",L15/D15) -> - | N15: =IF(D15=0,"-",E15/D15) -> - | O15: =IF((F15+G15)=0,"-",D15/(F15+G15)) -> - | P15: =P14+L15 -> 0
A16: 46062 | B16: 0 | C16: 0 | D16: =B16-C16 -> 0 | E16: 0 | F16: 0 | G16: 0 | H16: =F16*$A$5 -> 0 | I16: =G16*$D$5 -> 0 | J16: =B16*$G$5 -> 0 | K16: =E16+F16+G16+H16+I16+J16 -> 0 | L16: =D16-K16 -> 0 | M16: =IF(D16=0,"-",L16/D16) -> - | N16: =IF(D16=0,"-",E16/D16) -> - | O16: =IF((F16+G16)=0,"-",D16/(F16+G16)) -> - | P16: =P15+L16 -> 0
A17: 46063 | B17: 0 | C17: 0 | D17: =B17-C17 -> 0 | E17: 0 | F17: 0 | G17: 0 | H17: =F17*$A$5 -> 0 | I17: =G17*$D$5 -> 0 | J17: =B17*$G$5 -> 0 | K17: =E17+F17+G17+H17+I17+J17 -> 0 | L17: =D17-K17 -> 0 | M17: =IF(D17=0,"-",L17/D17) -> - | N17: =IF(D17=0,"-",E17/D17) -> - | O17: =IF((F17+G17)=0,"-",D17/(F17+G17)) -> - | P17: =P16+L17 -> 0
A18: 46064 | B18: 0 | C18: 0 | D18: =B18-C18 -> 0 | E18: 0 | F18: 0 | G18: 0 | H18: =F18*$A$5 -> 0 | I18: =G18*$D$5 -> 0 | J18: =B18*$G$5 -> 0 | K18: =E18+F18+G18+H18+I18+J18 -> 0 | L18: =D18-K18 -> 0 | M18: =IF(D18=0,"-",L18/D18) -> - | N18: =IF(D18=0,"-",E18/D18) -> - | O18: =IF((F18+G18)=0,"-",D18/(F18+G18)) -> - | P18: =P17+L18 -> 0
A19: 46065 | B19: 0 | C19: 0 | D19: =B19-C19 -> 0 | E19: 0 | F19: 0 | G19: 0 | H19: =F19*$A$5 -> 0 | I19: =G19*$D$5 -> 0 | J19: =B19*$G$5 -> 0 | K19: =E19+F19+G19+H19+I19+J19 -> 0 | L19: =D19-K19 -> 0 | M19: =IF(D19=0,"-",L19/D19) -> - | N19: =IF(D19=0,"-",E19/D19) -> - | O19: =IF((F19+G19)=0,"-",D19/(F19+G19)) -> - | P19: =P18+L19 -> 0
A20: 46066 | B20: 0 | C20: 0 | D20: =B20-C20 -> 0 | E20: 0 | F20: 0 | G20: 0 | H20: =F20*$A$5 -> 0 | I20: =G20*$D$5 -> 0 | J20: =B20*$G$5 -> 0 | K20: =E20+F20+G20+H20+I20+J20 -> 0 | L20: =D20-K20 -> 0 | M20: =IF(D20=0,"-",L20/D20) -> - | N20: =IF(D20=0,"-",E20/D20) -> - | O20: =IF((F20+G20)=0,"-",D20/(F20+G20)) -> - | P20: =P19+L20 -> 0
... A35: 46081 | B35: 0 | C35: 0 | D35: =B35-C35 -> 0 | E35: 0 | F35: 0 | G35: 0 | H35: =F35*$A$5 -> 0 | I35: =G35*$D$5 -> 0 | J35: =B35*$G$5 -> 0 | K35: =E35+F35+G35+H35+I35+J35 -> 0 | L35: =D35-K35 -> 0 | M35: =IF(D35=0,"-",L35/D35) -> - | N35: =IF(D35=0,"-",E35/D35) -> - | O35: =IF((F35+G35)=0,"-",D35/(F35+G35)) -> - | P35: =P34+L35 -> 0
A36: TOTAL | B36: =SUM(B8:B35) -> 0 | C36: =SUM(C8:C35) -> 0 | D36: =SUM(D8:D35) -> 0 | E36: =SUM(E8:E35) -> 0 | F36: =SUM(F8:F35) -> 0 | G36: =SUM(G8:G35) -> 0 | H36: =SUM(H8:H35) -> 0 | I36: =SUM(I8:I35) -> 0 | ... L36: =SUM(L8:L35) -> 0 | M36: =IF(D36=0,"-",L36/D36) -> - | N36: =IF(D36=0,"-",E36/D36) -> - | O36: =IF((F36+G36)=0,"-",D36/(F36+G36)) -> - | P36: =L36 -> 0
A38: 🔵 Blue = enter manually | ⬜ White/Grey = auto-calculated | 🟡 Yellow = editable fee % | 🟢 Green = positive | 🟡 Amber = 0–15% margin | 🔴 Red = negative

Sheet March
A2: 📊 Profit & Loss — March 2026 | N2: ="Currency: "&'⚙ Settings'!C6 -> Currency: €
A4: Agency Fee — Facebook | D4: Agency Fee — Google | G4: Transaction Fee | J4: 💡 Edit the coloured % cells above to update all fee calculations for this month automatically
A5: 0.06 | D5: 0.1 | G5: 0.05
A7: Date | B7: Gross Revenue | C7: Refunds | D7: Net Revenue | E7: Cost of Goods | F7: Adspend Facebook | G7: Adspend Google | H7: Agency Fee FB | I7: Agency Fee Google | J7: Transaction Fee | K7: Total Costs | L7: Profit | M7: Profit Margin % | N7: COG Impact % | O7: ROAS | P7: Cumulative Profit | Q7: Notes
A8: 46082 | B8: 0 | C8: 0 | D8: =B8-C8 -> 0 | E8: 0 | F8: 0 | G8: 0 | H8: =F8*$A$5 -> 0 | I8: =G8*$D$5 -> 0 | J8: =B8*$G$5 -> 0 | K8: =E8+F8+G8+H8+I8+J8 -> 0 | L8: =D8-K8 -> 0 | M8: =IF(D8=0,"-",L8/D8) -> - | N8: =IF(D8=0,"-",E8/D8) -> - | O8: =IF((F8+G8)=0,"-",D8/(F8+G8)) -> - | P8: =L8 -> 0
A9: 46083 | B9: 0 | C9: 0 | D9: =B9-C9 -> 0 | E9: 0 | F9: 0 | G9: 0 | H9: =F9*$A$5 -> 0 | I9: =G9*$D$5 -> 0 | J9: =B9*$G$5 -> 0 | K9: =E9+F9+G9+H9+I9+J9 -> 0 | L9: =D9-K9 -> 0 | M9: =IF(D9=0,"-",L9/D9) -> - | N9: =IF(D9=0,"-",E9/D9) -> - | O9: =IF((F9+G9)=0,"-",D9/(F9+G9)) -> - | P9: =P8+L9 -> 0
A10: 46084 | B10: 0 | C10: 0 | D10: =B10-C10 -> 0 | E10: 0 | F10: 0 | G10: 0 | H10: =F10*$A$5 -> 0 | I10: =G10*$D$5 -> 0 | J10: =B10*$G$5 -> 0 | K10: =E10+F10+G10+H10+I10+J10 -> 0 | L10: =D10-K10 -> 0 | M10: =IF(D10=0,"-",L10/D10) -> - | N10: =IF(D10=0,"-",E10/D10) -> - | O10: =IF((F10+G10)=0,"-",D10/(F10+G10)) -> - | P10: =P9+L10 -> 0
A11: 46085 | B11: 0 | C11: 0 | D11: =B11-C11 -> 0 | E11: 0 | F11: 0 | G11: 0 | H11: =F11*$A$5 -> 0 | I11: =G11*$D$5 -> 0 | J11: =B11*$G$5 -> 0 | K11: =E11+F11+G11+H11+I11+J11 -> 0 | L11: =D11-K11 -> 0 | M11: =IF(D11=0,"-",L11/D11) -> - | N11: =IF(D11=0,"-",E11/D11) -> - | O11: =IF((F11+G11)=0,"-",D11/(F11+G11)) -> - | P11: =P10+L11 -> 0
A12: 46086 | B12: 0 | C12: 0 | D12: =B12-C12 -> 0 | E12: 0 | F12: 0 | G12: 0 | H12: =F12*$A$5 -> 0 | I12: =G12*$D$5 -> 0 | J12: =B12*$G$5 -> 0 | K12: =E12+F12+G12+H12+I12+J12 -> 0 | L12: =D12-K12 -> 0 | M12: =IF(D12=0,"-",L12/D12) -> - | N12: =IF(D12=0,"-",E12/D12) -> - | O12: =IF((F12+G12)=0,"-",D12/(F12+G12)) -> - | P12: =P11+L12 -> 0
A13: 46087 | B13: 0 | C13: 0 | D13: =B13-C13 -> 0 | E13: 0 | F13: 0 | G13: 0 | H13: =F13*$A$5 -> 0 | I13: =G13*$D$5 -> 0 | J13: =B13*$G$5 -> 0 | K13: =E13+F13+G13+H13+I13+J13 -> 0 | L13: =D13-K13 -> 0 | M13: =IF(D13=0,"-",L13/D13) -> - | N13: =IF(D13=0,"-",E13/D13) -> - | O13: =IF((F13+G13)=0,"-",D13/(F13+G13)) -> - | P13: =P12+L13 -> 0
A14: 46088 | B14: 0 | C14: 0 | D14: =B14-C14 -> 0 | E14: 0 | F14: 0 | G14: 0 | H14: =F14*$A$5 -> 0 | I14: =G14*$D$5 -> 0 | J14: =B14*$G$5 -> 0 | K14: =E14+F14+G14+H14+I14+J14 -> 0 | L14: =D14-K14 -> 0 | M14: =IF(D14=0,"-",L14/D14) -> - | N14: =IF(D14=0,"-",E14/D14) -> - | O14: =IF((F14+G14)=0,"-",D14/(F14+G14)) -> - | P14: =P13+L14 -> 0
A15: 46089 | B15: 0 | C15: 0 | D15: =B15-C15 -> 0 | E15: 0 | F15: 0 | G15: 0 | H15: =F15*$A$5 -> 0 | I15: =G15*$D$5 -> 0 | J15: =B15*$G$5 -> 0 | K15: =E15+F15+G15+H15+I15+J15 -> 0 | L15: =D15-K15 -> 0 | M15: =IF(D15=0,"-",L15/D15) -> - | N15: =IF(D15=0,"-",E15/D15) -> - | O15: =IF((F15+G15)=0,"-",D15/(F15+G15)) -> - | P15: =P14+L15 -> 0
A16: 46090 | B16: 0 | C16: 0 | D16: =B16-C16 -> 0 | E16: 0 | F16: 0 | G16: 0 | H16: =F16*$A$5 -> 0 | I16: =G16*$D$5 -> 0 | J16: =B16*$G$5 -> 0 | K16: =E16+F16+G16+H16+I16+J16 -> 0 | L16: =D16-K16 -> 0 | M16: =IF(D16=0,"-",L16/D16) -> - | N16: =IF(D16=0,"-",E16/D16) -> - | O16: =IF((F16+G16)=0,"-",D16/(F16+G16)) -> - | P16: =P15+L16 -> 0
A17: 46091 | B17: 0 | C17: 0 | D17: =B17-C17 -> 0 | E17: 0 | F17: 0 | G17: 0 | H17: =F17*$A$5 -> 0 | I17: =G17*$D$5 -> 0 | J17: =B17*$G$5 -> 0 | K17: =E17+F17+G17+H17+I17+J17 -> 0 | L17: =D17-K17 -> 0 | M17: =IF(D17=0,"-",L17/D17) -> - | N17: =IF(D17=0,"-",E17/D17) -> - | O17: =IF((F17+G17)=0,"-",D17/(F17+G17)) -> - | P17: =P16+L17 -> 0
A18: 46092 | B18: 0 | C18: 0 | D18: =B18-C18 -> 0 | E18: 0 | F18: 0 | G18: 0 | H18: =F18*$A$5 -> 0 | I18: =G18*$D$5 -> 0 | J18: =B18*$G$5 -> 0 | K18: =E18+F18+G18+H18+I18+J18 -> 0 | L18: =D18-K18 -> 0 | M18: =IF(D18=0,"-",L18/D18) -> - | N18: =IF(D18=0,"-",E18/D18) -> - | O18: =IF((F18+G18)=0,"-",D18/(F18+G18)) -> - | P18: =P17+L18 -> 0
A19: 46093 | B19: 0 | C19: 0 | D19: =B19-C19 -> 0 | E19: 0 | F19: 0 | G19: 0 | H19: =F19*$A$5 -> 0 | I19: =G19*$D$5 -> 0 | J19: =B19*$G$5 -> 0 | K19: =E19+F19+G19+H19+I19+J19 -> 0 | L19: =D19-K19 -> 0 | M19: =IF(D19=0,"-",L19/D19) -> - | N19: =IF(D19=0,"-",E19/D19) -> - | O19: =IF((F19+G19)=0,"-",D19/(F19+G19)) -> - | P19: =P18+L19 -> 0
A20: 46094 | B20: 0 | C20: 0 | D20: =B20-C20 -> 0 | E20: 0 | F20: 0 | G20: 0 | H20: =F20*$A$5 -> 0 | I20: =G20*$D$5 -> 0 | J20: =B20*$G$5 -> 0 | K20: =E20+F20+G20+H20+I20+J20 -> 0 | L20: =D20-K20 -> 0 | M20: =IF(D20=0,"-",L20/D20) -> - | N20: =IF(D20=0,"-",E20/D20) -> - | O20: =IF((F20+G20)=0,"-",D20/(F20+G20)) -> - | P20: =P19+L20 -> 0
... A38: 46112 | B38: 0 | C38: 0 | D38: =B38-C38 -> 0 | E38: 0 | F38: 0 | G38: 0 | H38: =F38*$A$5 -> 0 | I38: =G38*$D$5 -> 0 | J38: =B38*$G$5 -> 0 | K38: =E38+F38+G38+H38+I38+J38 -> 0 | L38: =D38-K38 -> 0 | M38: =IF(D38=0,"-",L38/D38) -> - | N38: =IF(D38=0,"-",E38/D38) -> - | O38: =IF((F38+G38)=0,"-",D38/(F38+G38)) -> - | P38: =P37+L38 -> 0
A39: TOTAL | B39: =SUM(B8:B38) -> 0 | C39: =SUM(C8:C38) -> 0 | D39: =SUM(D8:D38) -> 0 | E39: =SUM(E8:E38) -> 0 | F39: =SUM(F8:F38) -> 0 | G39: =SUM(G8:G38) -> 0 | H39: =SUM(H8:H38) -> 0 | I39: =SUM(I8:I38) -> 0 | ... L39: =SUM(L8:L38) -> 0 | M39: =IF(D39=0,"-",L39/D39) -> - | N39: =IF(D39=0,"-",E39/D39) -> - | O39: =IF((F39+G39)=0,"-",D39/(F39+G39)) -> - | P39: =L39 -> 0
A41: 🔵 Blue = enter manually | ⬜ White/Grey = auto-calculated | 🟡 Yellow = editable fee % | 🟢 Green = positive | 🟡 Amber = 0–15% margin | 🔴 Red = negative

Sheet April
A2: 📊 Profit & Loss — April 2026 | N2: ="Currency: "&'⚙ Settings'!C6 -> Currency: €
A4: Agency Fee — Facebook | D4: Agency Fee — Google | G4: Transaction Fee | J4: 💡 Edit the coloured % cells above to update all fee calculations for this month automatically
A5: 0.06 | D5: 0.1 | G5: 0.05
A7: Date | B7: Gross Revenue | C7: Refunds | D7: Net Revenue | E7: Cost of Goods | F7: Adspend Facebook | G7: Adspend Google | H7: Agency Fee FB | I7: Agency Fee Google | J7: Transaction Fee | K7: Total Costs | L7: Profit | M7: Profit Margin % | N7: COG Impact % | O7: ROAS | P7: Cumulative Profit | Q7: Notes
A8: 46113 | B8: 0 | C8: 0 | D8: =B8-C8 -> 0 | E8: 0 | F8: 0 | G8: 0 | H8: =F8*$A$5 -> 0 | I8: =G8*$D$5 -> 0 | J8: =B8*$G$5 -> 0 | K8: =E8+F8+G8+H8+I8+J8 -> 0 | L8: =D8-K8 -> 0 | M8: =IF(D8=0,"-",L8/D8) -> - | N8: =IF(D8=0,"-",E8/D8) -> - | O8: =IF((F8+G8)=0,"-",D8/(F8+G8)) -> - | P8: =L8 -> 0
A9: 46114 | B9: 0 | C9: 0 | D9: =B9-C9 -> 0 | E9: 0 | F9: 0 | G9: 0 | H9: =F9*$A$5 -> 0 | I9: =G9*$D$5 -> 0 | J9: =B9*$G$5 -> 0 | K9: =E9+F9+G9+H9+I9+J9 -> 0 | L9: =D9-K9 -> 0 | M9: =IF(D9=0,"-",L9/D9) -> - | N9: =IF(D9=0,"-",E9/D9) -> - | O9: =IF((F9+G9)=0,"-",D9/(F9+G9)) -> - | P9: =P8+L9 -> 0
A10: 46115 | B10: 0 | C10: 0 | D10: =B10-C10 -> 0 | E10: 0 | F10: 0 | G10: 0 | H10: =F10*$A$5 -> 0 | I10: =G10*$D$5 -> 0 | J10: =B10*$G$5 -> 0 | K10: =E10+F10+G10+H10+I10+J10 -> 0 | L10: =D10-K10 -> 0 | M10: =IF(D10=0,"-",L10/D10) -> - | N10: =IF(D10=0,"-",E10/D10) -> - | O10: =IF((F10+G10)=0,"-",D10/(F10+G10)) -> - | P10: =P9+L10 -> 0
A11: 46116 | B11: 0 | C11: 0 | D11: =B11-C11 -> 0 | E11: 0 | F11: 0 | G11: 0 | H11: =F11*$A$5 -> 0 | I11: =G11*$D$5 -> 0 | J11: =B11*$G$5 -> 0 | K11: =E11+F11+G11+H11+I11+J11 -> 0 | L11: =D11-K11 -> 0 | M11: =IF(D11=0,"-",L11/D11) -> - | N11: =IF(D11=0,"-",E11/D11) -> - | O11: =IF((F11+G11)=0,"-",D11/(F11+G11)) -> - | P11: =P10+L11 -> 0
A12: 46117 | B12: 0 | C12: 0 | D12: =B12-C12 -> 0 | E12: 0 | F12: 0 | G12: 0 | H12: =F12*$A$5 -> 0 | I12: =G12*$D$5 -> 0 | J12: =B12*$G$5 -> 0 | K12: =E12+F12+G12+H12+I12+J12 -> 0 | L12: =D12-K12 -> 0 | M12: =IF(D12=0,"-",L12/D12) -> - | N12: =IF(D12=0,"-",E12/D12) -> - | O12: =IF((F12+G12)=0,"-",D12/(F12+G12)) -> - | P12: =P11+L12 -> 0
A13: 46118 | B13: 0 | C13: 0 | D13: =B13-C13 -> 0 | E13: 0 | F13: 0 | G13: 0 | H13: =F13*$A$5 -> 0 | I13: =G13*$D$5 -> 0 | J13: =B13*$G$5 -> 0 | K13: =E13+F13+G13+H13+I13+J13 -> 0 | L13: =D13-K13 -> 0 | M13: =IF(D13=0,"-",L13/D13) -> - | N13: =IF(D13=0,"-",E13/D13) -> - | O13: =IF((F13+G13)=0,"-",D13/(F13+G13)) -> - | P13: =P12+L13 -> 0
A14: 46119 | B14: 0 | C14: 0 | D14: =B14-C14 -> 0 | E14: 0 | F14: 0 | G14: 0 | H14: =F14*$A$5 -> 0 | I14: =G14*$D$5 -> 0 | J14: =B14*$G$5 -> 0 | K14: =E14+F14+G14+H14+I14+J14 -> 0 | L14: =D14-K14 -> 0 | M14: =IF(D14=0,"-",L14/D14) -> - | N14: =IF(D14=0,"-",E14/D14) -> - | O14: =IF((F14+G14)=0,"-",D14/(F14+G14)) -> - | P14: =P13+L14 -> 0
A15: 46120 | B15: 0 | C15: 0 | D15: =B15-C15 -> 0 | E15: 0 | F15: 0 | G15: 0 | H15: =F15*$A$5 -> 0 | I15: =G15*$D$5 -> 0 | J15: =B15*$G$5 -> 0 | K15: =E15+F15+G15+H15+I15+J15 -> 0 | L15: =D15-K15 -> 0 | M15: =IF(D15=0,"-",L15/D15) -> - | N15: =IF(D15=0,"-",E15/D15) -> - | O15: =IF((F15+G15)=0,"-",D15/(F15+G15)) -> - | P15: =P14+L15 -> 0
A16: 46121 | B16: 0 | C16: 0 | D16: =B16-C16 -> 0 | E16: 0 | F16: 0 | G16: 0 | H16: =F16*$A$5 -> 0 | I16: =G16*$D$5 -> 0 | J16: =B16*$G$5 -> 0 | K16: =E16+F16+G16+H16+I16+J16 -> 0 | L16: =D16-K16 -> 0 | M16: =IF(D16=0,"-",L16/D16) -> - | N16: =IF(D16=0,"-",E16/D16) -> - | O16: =IF((F16+G16)=0,"-",D16/(F16+G16)) -> - | P16: =P15+L16 -> 0
A17: 46122 | B17: 0 | C17: 0 | D17: =B17-C17 -> 0 | E17: 0 | F17: 0 | G17: 0 | H17: =F17*$A$5 -> 0 | I17: =G17*$D$5 -> 0 | J17: =B17*$G$5 -> 0 | K17: =E17+F17+G17+H17+I17+J17 -> 0 | L17: =D17-K17 -> 0 | M17: =IF(D17=0,"-",L17/D17) -> - | N17: =IF(D17=0,"-",E17/D17) -> - | O17: =IF((F17+G17)=0,"-",D17/(F17+G17)) -> - | P17: =P16+L17 -> 0
A18: 46123 | B18: 0 | C18: 0 | D18: =B18-C18 -> 0 | E18: 0 | F18: 0 | G18: 0 | H18: =F18*$A$5 -> 0 | I18: =G18*$D$5 -> 0 | J18: =B18*$G$5 -> 0 | K18: =E18+F18+G18+H18+I18+J18 -> 0 | L18: =D18-K18 -> 0 | M18: =IF(D18=0,"-",L18/D18) -> - | N18: =IF(D18=0,"-",E18/D18) -> - | O18: =IF((F18+G18)=0,"-",D18/(F18+G18)) -> - | P18: =P17+L18 -> 0
A19: 46124 | B19: 0 | C19: 0 | D19: =B19-C19 -> 0 | E19: 0 | F19: 0 | G19: 0 | H19: =F19*$A$5 -> 0 | I19: =G19*$D$5 -> 0 | J19: =B19*$G$5 -> 0 | K19: =E19+F19+G19+H19+I19+J19 -> 0 | L19: =D19-K19 -> 0 | M19: =IF(D19=0,"-",L19/D19) -> - | N19: =IF(D19=0,"-",E19/D19) -> - | O19: =IF((F19+G19)=0,"-",D19/(F19+G19)) -> - | P19: =P18+L19 -> 0
A20: 46125 | B20: 0 | C20: 0 | D20: =B20-C20 -> 0 | E20: 0 | F20: 0 | G20: 0 | H20: =F20*$A$5 -> 0 | I20: =G20*$D$5 -> 0 | J20: =B20*$G$5 -> 0 | K20: =E20+F20+G20+H20+I20+J20 -> 0 | L20: =D20-K20 -> 0 | M20: =IF(D20=0,"-",L20/D20) -> - | N20: =IF(D20=0,"-",E20/D20) -> - | O20: =IF((F20+G20)=0,"-",D20/(F20+G20)) -> - | P20: =P19+L20 -> 0
... A37: 46142 | B37: 0 | C37: 0 | D37: =B37-C37 -> 0 | E37: 0 | F37: 0 | G37: 0 | H37: =F37*$A$5 -> 0 | I37: =G37*$D$5 -> 0 | J37: =B37*$G$5 -> 0 | K37: =E37+F37+G37+H37+I37+J37 -> 0 | L37: =D37-K37 -> 0 | M37: =IF(D37=0,"-",L37/D37) -> - | N37: =IF(D37=0,"-",E37/D37) -> - | O37: =IF((F37+G37)=0,"-",D37/(F37+G37)) -> - | P37: =P36+L37 -> 0
A38: TOTAL | B38: =SUM(B8:B37) -> 0 | C38: =SUM(C8:C37) -> 0 | D38: =SUM(D8:D37) -> 0 | E38: =SUM(E8:E37) -> 0 | F38: =SUM(F8:F37) -> 0 | G38: =SUM(G8:G37) -> 0 | H38: =SUM(H8:H37) -> 0 | I38: =SUM(I8:I37) -> 0 | ... L38: =SUM(L8:L37) -> 0 | M38: =IF(D38=0,"-",L38/D38) -> - | N38: =IF(D38=0,"-",E38/D38) -> - | O38: =IF((F38+G38)=0,"-",D38/(F38+G38)) -> - | P38: =L38 -> 0
A40: 🔵 Blue = enter manually | ⬜ White/Grey = auto-calculated | 🟡 Yellow = editable fee % | 🟢 Green = positive | 🟡 Amber = 0–15% margin | 🔴 Red = negative

Sheet May
A2: 📊 Profit & Loss — May 2026 | N2: ="Currency: "&'⚙ Settings'!C6 -> Currency: €
A4: Agency Fee — Facebook | D4: Agency Fee — Google | G4: Transaction Fee | J4: 💡 Edit the coloured % cells above to update all fee calculations for this month automatically
A5: 0.06 | D5: 0.1 | G5: 0.05
A7: Date | B7: Gross Revenue | C7: Refunds | D7: Net Revenue | E7: Cost of Goods | F7: Adspend Facebook | G7: Adspend Google | H7: Agency Fee FB | I7: Agency Fee Google | J7: Transaction Fee | K7: Total Costs | L7: Profit | M7: Profit Margin % | N7: COG Impact % | O7: ROAS | P7: Cumulative Profit | Q7: Notes
A8: 46143 | B8: 0 | C8: 0 | D8: =B8-C8 -> 0 | E8: 0 | F8: 0 | G8: 0 | H8: =F8*$A$5 -> 0 | I8: =G8*$D$5 -> 0 | J8: =B8*$G$5 -> 0 | K8: =E8+F8+G8+H8+I8+J8 -> 0 | L8: =D8-K8 -> 0 | M8: =IF(D8=0,"-",L8/D8) -> - | N8: =IF(D8=0,"-",E8/D8) -> - | O8: =IF((F8+G8)=0,"-",D8/(F8+G8)) -> - | P8: =L8 -> 0
A9: 46144 | B9: 0 | C9: 0 | D9: =B9-C9 -> 0 | E9: 0 | F9: 0 | G9: 0 | H9: =F9*$A$5 -> 0 | I9: =G9*$D$5 -> 0 | J9: =B9*$G$5 -> 0 | K9: =E9+F9+G9+H9+I9+J9 -> 0 | L9: =D9-K9 -> 0 | M9: =IF(D9=0,"-",L9/D9) -> - | N9: =IF(D9=0,"-",E9/D9) -> - | O9: =IF((F9+G9)=0,"-",D9/(F9+G9)) -> - | P9: =P8+L9 -> 0
A10: 46145 | B10: 0 | C10: 0 | D10: =B10-C10 -> 0 | E10: 0 | F10: 0 | G10: 0 | H10: =F10*$A$5 -> 0 | I10: =G10*$D$5 -> 0 | J10: =B10*$G$5 -> 0 | K10: =E10+F10+G10+H10+I10+J10 -> 0 | L10: =D10-K10 -> 0 | M10: =IF(D10=0,"-",L10/D10) -> - | N10: =IF(D10=0,"-",E10/D10) -> - | O10: =IF((F10+G10)=0,"-",D10/(F10+G10)) -> - | P10: =P9+L10 -> 0
A11: 46146 | B11: 0 | C11: 0 | D11: =B11-C11 -> 0 | E11: 0 | F11: 0 | G11: 0 | H11: =F11*$A$5 -> 0 | I11: =G11*$D$5 -> 0 | J11: =B11*$G$5 -> 0 | K11: =E11+F11+G11+H11+I11+J11 -> 0 | L11: =D11-K11 -> 0 | M11: =IF(D11=0,"-",L11/D11) -> - | N11: =IF(D11=0,"-",E11/D11) -> - | O11: =IF((F11+G11)=0,"-",D11/(F11+G11)) -> - | P11: =P10+L11 -> 0
A12: 46147 | B12: 0 | C12: 0 | D12: =B12-C12 -> 0 | E12: 0 | F12: 0 | G12: 0 | H12: =F12*$A$5 -> 0 | I12: =G12*$D$5 -> 0 | J12: =B12*$G$5 -> 0 | K12: =E12+F12+G12+H12+I12+J12 -> 0 | L12: =D12-K12 -> 0 | M12: =IF(D12=0,"-",L12/D12) -> - | N12: =IF(D12=0,"-",E12/D12) -> - | O12: =IF((F12+G12)=0,"-",D12/(F12+G12)) -> - | P12: =P11+L12 -> 0
A13: 46148 | B13: 0 | C13: 0 | D13: =B13-C13 -> 0 | E13: 0 | F13: 0 | G13: 0 | H13: =F13*$A$5 -> 0 | I13: =G13*$D$5 -> 0 | J13: =B13*$G$5 -> 0 | K13: =E13+F13+G13+H13+I13+J13 -> 0 | L13: =D13-K13 -> 0 | M13: =IF(D13=0,"-",L13/D13) -> - | N13: =IF(D13=0,"-",E13/D13) -> - | O13: =IF((F13+G13)=0,"-",D13/(F13+G13)) -> - | P13: =P12+L13 -> 0
A14: 46149 | B14: 0 | C14: 0 | D14: =B14-C14 -> 0 | E14: 0 | F14: 0 | G14: 0 | H14: =F14*$A$5 -> 0 | I14: =G14*$D$5 -> 0 | J14: =B14*$G$5 -> 0 | K14: =E14+F14+G14+H14+I14+J14 -> 0 | L14: =D14-K14 -> 0 | M14: =IF(D14=0,"-",L14/D14) -> - | N14: =IF(D14=0,"-",E14/D14) -> - | O14: =IF((F14+G14)=0,"-",D14/(F14+G14)) -> - | P14: =P13+L14 -> 0
A15: 46150 | B15: 0 | C15: 0 | D15: =B15-C15 -> 0 | E15: 0 | F15: 0 | G15: 0 | H15: =F15*$A$5 -> 0 | I15: =G15*$D$5 -> 0 | J15: =B15*$G$5 -> 0 | K15: =E15+F15+G15+H15+I15+J15 -> 0 | L15: =D15-K15 -> 0 | M15: =IF(D15=0,"-",L15/D15) -> - | N15: =IF(D15=0,"-",E15/D15) -> - | O15: =IF((F15+G15)=0,"-",D15/(F15+G15)) -> - | P15: =P14+L15 -> 0
A16: 46151 | B16: 0 | C16: 0 | D16: =B16-C16 -> 0 | E16: 0 | F16: 0 | G16: 0 | H16: =F16*$A$5 -> 0 | I16: =G16*$D$5 -> 0 | J16: =B16*$G$5 -> 0 | K16: =E16+F16+G16+H16+I16+J16 -> 0 | L16: =D16-K16 -> 0 | M16: =IF(D16=0,"-",L16/D16) -> - | N16: =IF(D16=0,"-",E16/D16) -> - | O16: =IF((F16+G16)=0,"-",D16/(F16+G16)) -> - | P16: =P15+L16 -> 0
A17: 46152 | B17: 0 | C17: 0 | D17: =B17-C17 -> 0 | E17: 0 | F17: 0 | G17: 0 | H17: =F17*$A$5 -> 0 | I17: =G17*$D$5 -> 0 | J17: =B17*$G$5 -> 0 | K17: =E17+F17+G17+H17+I17+J17 -> 0 | L17: =D17-K17 -> 0 | M17: =IF(D17=0,"-",L17/D17) -> - | N17: =IF(D17=0,"-",E17/D17) -> - | O17: =IF((F17+G17)=0,"-",D17/(F17+G17)) -> - | P17: =P16+L17 -> 0
A18: 46153 | B18: 0 | C18: 0 | D18: =B18-C18 -> 0 | E18: 0 | F18: 0 | G18: 0 | H18: =F18*$A$5 -> 0 | I18: =G18*$D$5 -> 0 | J18: =B18*$G$5 -> 0 | K18: =E18+F18+G18+H18+I18+J18 -> 0 | L18: =D18-K18 -> 0 | M18: =IF(D18=0,"-",L18/D18) -> - | N18: =IF(D18=0,"-",E18/D18) -> - | O18: =IF((F18+G18)=0,"-",D18/(F18+G18)) -> - | P18: =P17+L18 -> 0
A19: 46154 | B19: 0 | C19: 0 | D19: =B19-C19 -> 0 | E19: 0 | F19: 0 | G19: 0 | H19: =F19*$A$5 -> 0 | I19: =G19*$D$5 -> 0 | J19: =B19*$G$5 -> 0 | K19: =E19+F19+G19+H19+I19+J19 -> 0 | L19: =D19-K19 -> 0 | M19: =IF(D19=0,"-",L19/D19) -> - | N19: =IF(D19=0,"-",E19/D19) -> - | O19: =IF((F19+G19)=0,"-",D19/(F19+G19)) -> - | P19: =P18+L19 -> 0
A20: 46155 | B20: 0 | C20: 0 | D20: =B20-C20 -> 0 | E20: 0 | F20: 0 | G20: 0 | H20: =F20*$A$5 -> 0 | I20: =G20*$D$5 -> 0 | J20: =B20*$G$5 -> 0 | K20: =E20+F20+G20+H20+I20+J20 -> 0 | L20: =D20-K20 -> 0 | M20: =IF(D20=0,"-",L20/D20) -> - | N20: =IF(D20=0,"-",E20/D20) -> - | O20: =IF((F20+G20)=0,"-",D20/(F20+G20)) -> - | P20: =P19+L20 -> 0
... A38: 46173 | B38: 0 | C38: 0 | D38: =B38-C38 -> 0 | E38: 0 | F38: 0 | G38: 0 | H38: =F38*$A$5 -> 0 | I38: =G38*$D$5 -> 0 | J38: =B38*$G$5 -> 0 | K38: =E38+F38+G38+H38+I38+J38 -> 0 | L38: =D38-K38 -> 0 | M38: =IF(D38=0,"-",L38/D38) -> - | N38: =IF(D38=0,"-",E38/D38) -> - | O38: =IF((F38+G38)=0,"-",D38/(F38+G38)) -> - | P38: =P37+L38 -> 0
A39: TOTAL | B39: =SUM(B8:B38) -> 0 | C39: =SUM(C8:C38) -> 0 | D39: =SUM(D8:D38) -> 0 | E39: =SUM(E8:E38) -> 0 | F39: =SUM(F8:F38) -> 0 | G39: =SUM(G8:G38) -> 0 | H39: =SUM(H8:H38) -> 0 | I39: =SUM(I8:I38) -> 0 | ... L39: =SUM(L8:L38) -> 0 | M39: =IF(D39=0,"-",L39/D39) -> - | N39: =IF(D39=0,"-",E39/D39) -> - | O39: =IF((F39+G39)=0,"-",D39/(F39+G39)) -> - | P39: =L39 -> 0
A41: 🔵 Blue = enter manually | ⬜ White/Grey = auto-calculated | 🟡 Yellow = editable fee % | 🟢 Green = positive | 🟡 Amber = 0–15% margin | 🔴 Red = negative

Sheet June
A2: 📊 Profit & Loss — June 2026 | N2: ="Currency: "&'⚙ Settings'!C6 -> Currency: €
A4: Agency Fee — Facebook | D4: Agency Fee — Google | G4: Transaction Fee | J4: 💡 Edit the coloured % cells above to update all fee calculations for this month automatically
A5: 0.06 | D5: 0.1 | G5: 0.05
A7: Date | B7: Gross Revenue | C7: Refunds | D7: Net Revenue | E7: Cost of Goods | F7: Adspend Facebook | G7: Adspend Google | H7: Agency Fee FB | I7: Agency Fee Google | J7: Transaction Fee | K7: Total Costs | L7: Profit | M7: Profit Margin % | N7: COG Impact % | O7: ROAS | P7: Cumulative Profit | Q7: Notes
A8: 46174 | B8: 0 | C8: 0 | D8: =B8-C8 -> 0 | E8: 0 | F8: 0 | G8: 0 | H8: =F8*$A$5 -> 0 | I8: =G8*$D$5 -> 0 | J8: =B8*$G$5 -> 0 | K8: =E8+F8+G8+H8+I8+J8 -> 0 | L8: =D8-K8 -> 0 | M8: =IF(D8=0,"-",L8/D8) -> - | N8: =IF(D8=0,"-",E8/D8) -> - | O8: =IF((F8+G8)=0,"-",D8/(F8+G8)) -> - | P8: =L8 -> 0
A9: 46175 | B9: 0 | C9: 0 | D9: =B9-C9 -> 0 | E9: 0 | F9: 0 | G9: 0 | H9: =F9*$A$5 -> 0 | I9: =G9*$D$5 -> 0 | J9: =B9*$G$5 -> 0 | K9: =E9+F9+G9+H9+I9+J9 -> 0 | L9: =D9-K9 -> 0 | M9: =IF(D9=0,"-",L9/D9) -> - | N9: =IF(D9=0,"-",E9/D9) -> - | O9: =IF((F9+G9)=0,"-",D9/(F9+G9)) -> - | P9: =P8+L9 -> 0
A10: 46176 | B10: 0 | C10: 0 | D10: =B10-C10 -> 0 | E10: 0 | F10: 0 | G10: 0 | H10: =F10*$A$5 -> 0 | I10: =G10*$D$5 -> 0 | J10: =B10*$G$5 -> 0 | K10: =E10+F10+G10+H10+I10+J10 -> 0 | L10: =D10-K10 -> 0 | M10: =IF(D10=0,"-",L10/D10) -> - | N10: =IF(D10=0,"-",E10/D10) -> - | O10: =IF((F10+G10)=0,"-",D10/(F10+G10)) -> - | P10: =P9+L10 -> 0
A11: 46177 | B11: 0 | C11: 0 | D11: =B11-C11 -> 0 | E11: 0 | F11: 0 | G11: 0 | H11: =F11*$A$5 -> 0 | I11: =G11*$D$5 -> 0 | J11: =B11*$G$5 -> 0 | K11: =E11+F11+G11+H11+I11+J11 -> 0 | L11: =D11-K11 -> 0 | M11: =IF(D11=0,"-",L11/D11) -> - | N11: =IF(D11=0,"-",E11/D11) -> - | O11: =IF((F11+G11)=0,"-",D11/(F11+G11)) -> - | P11: =P10+L11 -> 0
A12: 46178 | B12: 0 | C12: 0 | D12: =B12-C12 -> 0 | E12: 0 | F12: 0 | G12: 0 | H12: =F12*$A$5 -> 0 | I12: =G12*$D$5 -> 0 | J12: =B12*$G$5 -> 0 | K12: =E12+F12+G12+H12+I12+J12 -> 0 | L12: =D12-K12 -> 0 | M12: =IF(D12=0,"-",L12/D12) -> - | N12: =IF(D12=0,"-",E12/D12) -> - | O12: =IF((F12+G12)=0,"-",D12/(F12+G12)) -> - | P12: =P11+L12 -> 0
A13: 46179 | B13: 0 | C13: 0 | D13: =B13-C13 -> 0 | E13: 0 | F13: 0 | G13: 0 | H13: =F13*$A$5 -> 0 | I13: =G13*$D$5 -> 0 | J13: =B13*$G$5 -> 0 | K13: =E13+F13+G13+H13+I13+J13 -> 0 | L13: =D13-K13 -> 0 | M13: =IF(D13=0,"-",L13/D13) -> - | N13: =IF(D13=0,"-",E13/D13) -> - | O13: =IF((F13+G13)=0,"-",D13/(F13+G13)) -> - | P13: =P12+L13 -> 0
A14: 46180 | B14: 0 | C14: 0 | D14: =B14-C14 -> 0 | E14: 0 | F14: 0 | G14: 0 | H14: =F14*$A$5 -> 0 | I14: =G14*$D$5 -> 0 | J14: =B14*$G$5 -> 0 | K14: =E14+F14+G14+H14+I14+J14 -> 0 | L14: =D14-K14 -> 0 | M14: =IF(D14=0,"-",L14/D14) -> - | N14: =IF(D14=0,"-",E14/D14) -> - | O14: =IF((F14+G14)=0,"-",D14/(F14+G14)) -> - | P14: =P13+L14 -> 0
A15: 46181 | B15: 0 | C15: 0 | D15: =B15-C15 -> 0 | E15: 0 | F15: 0 | G15: 0 | H15: =F15*$A$5 -> 0 | I15: =G15*$D$5 -> 0 | J15: =B15*$G$5 -> 0 | K15: =E15+F15+G15+H15+I15+J15 -> 0 | L15: =D15-K15 -> 0 | M15: =IF(D15=0,"-",L15/D15) -> - | N15: =IF(D15=0,"-",E15/D15) -> - | O15: =IF((F15+G15)=0,"-",D15/(F15+G15)) -> - | P15: =P14+L15 -> 0
A16: 46182 | B16: 0 | C16: 0 | D16: =B16-C16 -> 0 | E16: 0 | F16: 0 | G16: 0 | H16: =F16*$A$5 -> 0 | I16: =G16*$D$5 -> 0 | J16: =B16*$G$5 -> 0 | K16: =E16+F16+G16+H16+I16+J16 -> 0 | L16: =D16-K16 -> 0 | M16: =IF(D16=0,"-",L16/D16) -> - | N16: =IF(D16=0,"-",E16/D16) -> - | O16: =IF((F16+G16)=0,"-",D16/(F16+G16)) -> - | P16: =P15+L16 -> 0
A17: 46183 | B17: 0 | C17: 0 | D17: =B17-C17 -> 0 | E17: 0 | F17: 0 | G17: 0 | H17: =F17*$A$5 -> 0 | I17: =G17*$D$5 -> 0 | J17: =B17*$G$5 -> 0 | K17: =E17+F17+G17+H17+I17+J17 -> 0 | L17: =D17-K17 -> 0 | M17: =IF(D17=0,"-",L17/D17) -> - | N17: =IF(D17=0,"-",E17/D17) -> - | O17: =IF((F17+G17)=0,"-",D17/(F17+G17)) -> - | P17: =P16+L17 -> 0
A18: 46184 | B18: 0 | C18: 0 | D18: =B18-C18 -> 0 | E18: 0 | F18: 0 | G18: 0 | H18: =F18*$A$5 -> 0 | I18: =G18*$D$5 -> 0 | J18: =B18*$G$5 -> 0 | K18: =E18+F18+G18+H18+I18+J18 -> 0 | L18: =D18-K18 -> 0 | M18: =IF(D18=0,"-",L18/D18) -> - | N18: =IF(D18=0,"-",E18/D18) -> - | O18: =IF((F18+G18)=0,"-",D18/(F18+G18)) -> - | P18: =P17+L18 -> 0
A19: 46185 | B19: 0 | C19: 0 | D19: =B19-C19 -> 0 | E19: 0 | F19: 0 | G19: 0 | H19: =F19*$A$5 -> 0 | I19: =G19*$D$5 -> 0 | J19: =B19*$G$5 -> 0 | K19: =E19+F19+G19+H19+I19+J19 -> 0 | L19: =D19-K19 -> 0 | M19: =IF(D19=0,"-",L19/D19) -> - | N19: =IF(D19=0,"-",E19/D19) -> - | O19: =IF((F19+G19)=0,"-",D19/(F19+G19)) -> - | P19: =P18+L19 -> 0
A20: 46186 | B20: 0 | C20: 0 | D20: =B20-C20 -> 0 | E20: 0 | F20: 0 | G20: 0 | H20: =F20*$A$5 -> 0 | I20: =G20*$D$5 -> 0 | J20: =B20*$G$5 -> 0 | K20: =E20+F20+G20+H20+I20+J20 -> 0 | L20: =D20-K20 -> 0 | M20: =IF(D20=0,"-",L20/D20) -> - | N20: =IF(D20=0,"-",E20/D20) -> - | O20: =IF((F20+G20)=0,"-",D20/(F20+G20)) -> - | P20: =P19+L20 -> 0
... A37: 46203 | B37: 0 | C37: 0 | D37: =B37-C37 -> 0 | E37: 0 | F37: 0 | G37: 0 | H37: =F37*$A$5 -> 0 | I37: =G37*$D$5 -> 0 | J37: =B37*$G$5 -> 0 | K37: =E37+F37+G37+H37+I37+J37 -> 0 | L37: =D37-K37 -> 0 | M37: =IF(D37=0,"-",L37/D37) -> - | N37: =IF(D37=0,"-",E37/D37) -> - | O37: =IF((F37+G37)=0,"-",D37/(F37+G37)) -> - | P37: =P36+L37 -> 0
A38: TOTAL | B38: =SUM(B8:B37) -> 0 | C38: =SUM(C8:C37) -> 0 | D38: =SUM(D8:D37) -> 0 | E38: =SUM(E8:E37) -> 0 | F38: =SUM(F8:F37) -> 0 | G38: =SUM(G8:G37) -> 0 | H38: =SUM(H8:H37) -> 0 | I38: =SUM(I8:I37) -> 0 | ... L38: =SUM(L8:L37) -> 0 | M38: =IF(D38=0,"-",L38/D38) -> - | N38: =IF(D38=0,"-",E38/D38) -> - | O38: =IF((F38+G38)=0,"-",D38/(F38+G38)) -> - | P38: =L38 -> 0
A40: 🔵 Blue = enter manually | ⬜ White/Grey = auto-calculated | 🟡 Yellow = editable fee % | 🟢 Green = positive | 🟡 Amber = 0–15% margin | 🔴 Red = negative

Sheet July
A2: 📊 Profit & Loss — July 2026 | N2: ="Currency: "&'⚙ Settings'!C6 -> Currency: €
A4: Agency Fee — Facebook | D4: Agency Fee — Google | G4: Transaction Fee | J4: 💡 Edit the coloured % cells above to update all fee calculations for this month automatically
A5: 0.06 | D5: 0.1 | G5: 0.05
A7: Date | B7: Gross Revenue | C7: Refunds | D7: Net Revenue | E7: Cost of Goods | F7: Adspend Facebook | G7: Adspend Google | H7: Agency Fee FB | I7: Agency Fee Google | J7: Transaction Fee | K7: Total Costs | L7: Profit | M7: Profit Margin % | N7: COG Impact % | O7: ROAS | P7: Cumulative Profit | Q7: Notes
A8: 46204 | B8: 0 | C8: 0 | D8: =B8-C8 -> 0 | E8: 0 | F8: 0 | G8: 0 | H8: =F8*$A$5 -> 0 | I8: =G8*$D$5 -> 0 | J8: =B8*$G$5 -> 0 | K8: =E8+F8+G8+H8+I8+J8 -> 0 | L8: =D8-K8 -> 0 | M8: =IF(D8=0,"-",L8/D8) -> - | N8: =IF(D8=0,"-",E8/D8) -> - | O8: =IF((F8+G8)=0,"-",D8/(F8+G8)) -> - | P8: =L8 -> 0
A9: 46205 | B9: 0 | C9: 0 | D9: =B9-C9 -> 0 | E9: 0 | F9: 0 | G9: 0 | H9: =F9*$A$5 -> 0 | I9: =G9*$D$5 -> 0 | J9: =B9*$G$5 -> 0 | K9: =E9+F9+G9+H9+I9+J9 -> 0 | L9: =D9-K9 -> 0 | M9: =IF(D9=0,"-",L9/D9) -> - | N9: =IF(D9=0,"-",E9/D9) -> - | O9: =IF((F9+G9)=0,"-",D9/(F9+G9)) -> - | P9: =P8+L9 -> 0
A10: 46206 | B10: 0 | C10: 0 | D10: =B10-C10 -> 0 | E10: 0 | F10: 0 | G10: 0 | H10: =F10*$A$5 -> 0 | I10: =G10*$D$5 -> 0 | J10: =B10*$G$5 -> 0 | K10: =E10+F10+G10+H10+I10+J10 -> 0 | L10: =D10-K10 -> 0 | M10: =IF(D10=0,"-",L10/D10) -> - | N10: =IF(D10=0,"-",E10/D10) -> - | O10: =IF((F10+G10)=0,"-",D10/(F10+G10)) -> - | P10: =P9+L10 -> 0
A11: 46207 | B11: 0 | C11: 0 | D11: =B11-C11 -> 0 | E11: 0 | F11: 0 | G11: 0 | H11: =F11*$A$5 -> 0 | I11: =G11*$D$5 -> 0 | J11: =B11*$G$5 -> 0 | K11: =E11+F11+G11+H11+I11+J11 -> 0 | L11: =D11-K11 -> 0 | M11: =IF(D11=0,"-",L11/D11) -> - | N11: =IF(D11=0,"-",E11/D11) -> - | O11: =IF((F11+G11)=0,"-",D11/(F11+G11)) -> - | P11: =P10+L11 -> 0
A12: 46208 | B12: 0 | C12: 0 | D12: =B12-C12 -> 0 | E12: 0 | F12: 0 | G12: 0 | H12: =F12*$A$5 -> 0 | I12: =G12*$D$5 -> 0 | J12: =B12*$G$5 -> 0 | K12: =E12+F12+G12+H12+I12+J12 -> 0 | L12: =D12-K12 -> 0 | M12: =IF(D12=0,"-",L12/D12) -> - | N12: =IF(D12=0,"-",E12/D12) -> - | O12: =IF((F12+G12)=0,"-",D12/(F12+G12)) -> - | P12: =P11+L12 -> 0
A13: 46209 | B13: 0 | C13: 0 | D13: =B13-C13 -> 0 | E13: 0 | F13: 0 | G13: 0 | H13: =F13*$A$5 -> 0 | I13: =G13*$D$5 -> 0 | J13: =B13*$G$5 -> 0 | K13: =E13+F13+G13+H13+I13+J13 -> 0 | L13: =D13-K13 -> 0 | M13: =IF(D13=0,"-",L13/D13) -> - | N13: =IF(D13=0,"-",E13/D13) -> - | O13: =IF((F13+G13)=0,"-",D13/(F13+G13)) -> - | P13: =P12+L13 -> 0
A14: 46210 | B14: 0 | C14: 0 | D14: =B14-C14 -> 0 | E14: 0 | F14: 0 | G14: 0 | H14: =F14*$A$5 -> 0 | I14: =G14*$D$5 -> 0 | J14: =B14*$G$5 -> 0 | K14: =E14+F14+G14+H14+I14+J14 -> 0 | L14: =D14-K14 -> 0 | M14: =IF(D14=0,"-",L14/D14) -> - | N14: =IF(D14=0,"-",E14/D14) -> - | O14: =IF((F14+G14)=0,"-",D14/(F14+G14)) -> - | P14: =P13+L14 -> 0
A15: 46211 | B15: 0 | C15: 0 | D15: =B15-C15 -> 0 | E15: 0 | F15: 0 | G15: 0 | H15: =F15*$A$5 -> 0 | I15: =G15*$D$5 -> 0 | J15: =B15*$G$5 -> 0 | K15: =E15+F15+G15+H15+I15+J15 -> 0 | L15: =D15-K15 -> 0 | M15: =IF(D15=0,"-",L15/D15) -> - | N15: =IF(D15=0,"-",E15/D15) -> - | O15: =IF((F15+G15)=0,"-",D15/(F15+G15)) -> - | P15: =P14+L15 -> 0
A16: 46212 | B16: 0 | C16: 0 | D16: =B16-C16 -> 0 | E16: 0 | F16: 0 | G16: 0 | H16: =F16*$A$5 -> 0 | I16: =G16*$D$5 -> 0 | J16: =B16*$G$5 -> 0 | K16: =E16+F16+G16+H16+I16+J16 -> 0 | L16: =D16-K16 -> 0 | M16: =IF(D16=0,"-",L16/D16) -> - | N16: =IF(D16=0,"-",E16/D16) -> - | O16: =IF((F16+G16)=0,"-",D16/(F16+G16)) -> - | P16: =P15+L16 -> 0
A17: 46213 | B17: 0 | C17: 0 | D17: =B17-C17 -> 0 | E17: 0 | F17: 0 | G17: 0 | H17: =F17*$A$5 -> 0 | I17: =G17*$D$5 -> 0 | J17: =B17*$G$5 -> 0 | K17: =E17+F17+G17+H17+I17+J17 -> 0 | L17: =D17-K17 -> 0 | M17: =IF(D17=0,"-",L17/D17) -> - | N17: =IF(D17=0,"-",E17/D17) -> - | O17: =IF((F17+G17)=0,"-",D17/(F17+G17)) -> - | P17: =P16+L17 -> 0
A18: 46214 | B18: 0 | C18: 0 | D18: =B18-C18 -> 0 | E18: 0 | F18: 0 | G18: 0 | H18: =F18*$A$5 -> 0 | I18: =G18*$D$5 -> 0 | J18: =B18*$G$5 -> 0 | K18: =E18+F18+G18+H18+I18+J18 -> 0 | L18: =D18-K18 -> 0 | M18: =IF(D18=0,"-",L18/D18) -> - | N18: =IF(D18=0,"-",E18/D18) -> - | O18: =IF((F18+G18)=0,"-",D18/(F18+G18)) -> - | P18: =P17+L18 -> 0
A19: 46215 | B19: 0 | C19: 0 | D19: =B19-C19 -> 0 | E19: 0 | F19: 0 | G19: 0 | H19: =F19*$A$5 -> 0 | I19: =G19*$D$5 -> 0 | J19: =B19*$G$5 -> 0 | K19: =E19+F19+G19+H19+I19+J19 -> 0 | L19: =D19-K19 -> 0 | M19: =IF(D19=0,"-",L19/D19) -> - | N19: =IF(D19=0,"-",E19/D19) -> - | O19: =IF((F19+G19)=0,"-",D19/(F19+G19)) -> - | P19: =P18+L19 -> 0
A20: 46216 | B20: 0 | C20: 0 | D20: =B20-C20 -> 0 | E20: 0 | F20: 0 | G20: 0 | H20: =F20*$A$5 -> 0 | I20: =G20*$D$5 -> 0 | J20: =B20*$G$5 -> 0 | K20: =E20+F20+G20+H20+I20+J20 -> 0 | L20: =D20-K20 -> 0 | M20: =IF(D20=0,"-",L20/D20) -> - | N20: =IF(D20=0,"-",E20/D20) -> - | O20: =IF((F20+G20)=0,"-",D20/(F20+G20)) -> - | P20: =P19+L20 -> 0
... A38: 46234 | B38: 0 | C38: 0 | D38: =B38-C38 -> 0 | E38: 0 | F38: 0 | G38: 0 | H38: =F38*$A$5 -> 0 | I38: =G38*$D$5 -> 0 | J38: =B38*$G$5 -> 0 | K38: =E38+F38+G38+H38+I38+J38 -> 0 | L38: =D38-K38 -> 0 | M38: =IF(D38=0,"-",L38/D38) -> - | N38: =IF(D38=0,"-",E38/D38) -> - | O38: =IF((F38+G38)=0,"-",D38/(F38+G38)) -> - | P38: =P37+L38 -> 0
A39: TOTAL | B39: =SUM(B8:B38) -> 0 | C39: =SUM(C8:C38) -> 0 | D39: =SUM(D8:D38) -> 0 | E39: =SUM(E8:E38) -> 0 | F39: =SUM(F8:F38) -> 0 | G39: =SUM(G8:G38) -> 0 | H39: =SUM(H8:H38) -> 0 | I39: =SUM(I8:I38) -> 0 | ... L39: =SUM(L8:L38) -> 0 | M39: =IF(D39=0,"-",L39/D39) -> - | N39: =IF(D39=0,"-",E39/D39) -> - | O39: =IF((F39+G39)=0,"-",D39/(F39+G39)) -> - | P39: =L39 -> 0
A41: 🔵 Blue = enter manually | ⬜ White/Grey = auto-calculated | 🟡 Yellow = editable fee % | 🟢 Green = positive | 🟡 Amber = 0–15% margin | 🔴 Red = negative

Sheet August
A2: 📊 Profit & Loss — August 2026 | N2: ="Currency: "&'⚙ Settings'!C6 -> Currency: €
A4: Agency Fee — Facebook | D4: Agency Fee — Google | G4: Transaction Fee | J4: 💡 Edit the coloured % cells above to update all fee calculations for this month automatically
A5: 0.06 | D5: 0.1 | G5: 0.05
A7: Date | B7: Gross Revenue | C7: Refunds | D7: Net Revenue | E7: Cost of Goods | F7: Adspend Facebook | G7: Adspend Google | H7: Agency Fee FB | I7: Agency Fee Google | J7: Transaction Fee | K7: Total Costs | L7: Profit | M7: Profit Margin % | N7: COG Impact % | O7: ROAS | P7: Cumulative Profit | Q7: Notes
A8: 46235 | B8: 0 | C8: 0 | D8: =B8-C8 -> 0 | E8: 0 | F8: 0 | G8: 0 | H8: =F8*$A$5 -> 0 | I8: =G8*$D$5 -> 0 | J8: =B8*$G$5 -> 0 | K8: =E8+F8+G8+H8+I8+J8 -> 0 | L8: =D8-K8 -> 0 | M8: =IF(D8=0,"-",L8/D8) -> - | N8: =IF(D8=0,"-",E8/D8) -> - | O8: =IF((F8+G8)=0,"-",D8/(F8+G8)) -> - | P8: =L8 -> 0
A9: 46236 | B9: 0 | C9: 0 | D9: =B9-C9 -> 0 | E9: 0 | F9: 0 | G9: 0 | H9: =F9*$A$5 -> 0 | I9: =G9*$D$5 -> 0 | J9: =B9*$G$5 -> 0 | K9: =E9+F9+G9+H9+I9+J9 -> 0 | L9: =D9-K9 -> 0 | M9: =IF(D9=0,"-",L9/D9) -> - | N9: =IF(D9=0,"-",E9/D9) -> - | O9: =IF((F9+G9)=0,"-",D9/(F9+G9)) -> - | P9: =P8+L9 -> 0
A10: 46237 | B10: 0 | C10: 0 | D10: =B10-C10 -> 0 | E10: 0 | F10: 0 | G10: 0 | H10: =F10*$A$5 -> 0 | I10: =G10*$D$5 -> 0 | J10: =B10*$G$5 -> 0 | K10: =E10+F10+G10+H10+I10+J10 -> 0 | L10: =D10-K10 -> 0 | M10: =IF(D10=0,"-",L10/D10) -> - | N10: =IF(D10=0,"-",E10/D10) -> - | O10: =IF((F10+G10)=0,"-",D10/(F10+G10)) -> - | P10: =P9+L10 -> 0
A11: 46238 | B11: 0 | C11: 0 | D11: =B11-C11 -> 0 | E11: 0 | F11: 0 | G11: 0 | H11: =F11*$A$5 -> 0 | I11: =G11*$D$5 -> 0 | J11: =B11*$G$5 -> 0 | K11: =E11+F11+G11+H11+I11+J11 -> 0 | L11: =D11-K11 -> 0 | M11: =IF(D11=0,"-",L11/D11) -> - | N11: =IF(D11=0,"-",E11/D11) -> - | O11: =IF((F11+G11)=0,"-",D11/(F11+G11)) -> - | P11: =P10+L11 -> 0
A12: 46239 | B12: 0 | C12: 0 | D12: =B12-C12 -> 0 | E12: 0 | F12: 0 | G12: 0 | H12: =F12*$A$5 -> 0 | I12: =G12*$D$5 -> 0 | J12: =B12*$G$5 -> 0 | K12: =E12+F12+G12+H12+I12+J12 -> 0 | L12: =D12-K12 -> 0 | M12: =IF(D12=0,"-",L12/D12) -> - | N12: =IF(D12=0,"-",E12/D12) -> - | O12: =IF((F12+G12)=0,"-",D12/(F12+G12)) -> - | P12: =P11+L12 -> 0
A13: 46240 | B13: 0 | C13: 0 | D13: =B13-C13 -> 0 | E13: 0 | F13: 0 | G13: 0 | H13: =F13*$A$5 -> 0 | I13: =G13*$D$5 -> 0 | J13: =B13*$G$5 -> 0 | K13: =E13+F13+G13+H13+I13+J13 -> 0 | L13: =D13-K13 -> 0 | M13: =IF(D13=0,"-",L13/D13) -> - | N13: =IF(D13=0,"-",E13/D13) -> - | O13: =IF((F13+G13)=0,"-",D13/(F13+G13)) -> - | P13: =P12+L13 -> 0
A14: 46241 | B14: 0 | C14: 0 | D14: =B14-C14 -> 0 | E14: 0 | F14: 0 | G14: 0 | H14: =F14*$A$5 -> 0 | I14: =G14*$D$5 -> 0 | J14: =B14*$G$5 -> 0 | K14: =E14+F14+G14+H14+I14+J14 -> 0 | L14: =D14-K14 -> 0 | M14: =IF(D14=0,"-",L14/D14) -> - | N14: =IF(D14=0,"-",E14/D14) -> - | O14: =IF((F14+G14)=0,"-",D14/(F14+G14)) -> - | P14: =P13+L14 -> 0
A15: 46242 | B15: 0 | C15: 0 | D15: =B15-C15 -> 0 | E15: 0 | F15: 0 | G15: 0 | H15: =F15*$A$5 -> 0 | I15: =G15*$D$5 -> 0 | J15: =B15*$G$5 -> 0 | K15: =E15+F15+G15+H15+I15+J15 -> 0 | L15: =D15-K15 -> 0 | M15: =IF(D15=0,"-",L15/D15) -> - | N15: =IF(D15=0,"-",E15/D15) -> - | O15: =IF((F15+G15)=0,"-",D15/(F15+G15)) -> - | P15: =P14+L15 -> 0
A16: 46243 | B16: 0 | C16: 0 | D16: =B16-C16 -> 0 | E16: 0 | F16: 0 | G16: 0 | H16: =F16*$A$5 -> 0 | I16: =G16*$D$5 -> 0 | J16: =B16*$G$5 -> 0 | K16: =E16+F16+G16+H16+I16+J16 -> 0 | L16: =D16-K16 -> 0 | M16: =IF(D16=0,"-",L16/D16) -> - | N16: =IF(D16=0,"-",E16/D16) -> - | O16: =IF((F16+G16)=0,"-",D16/(F16+G16)) -> - | P16: =P15+L16 -> 0
A17: 46244 | B17: 0 | C17: 0 | D17: =B17-C17 -> 0 | E17: 0 | F17: 0 | G17: 0 | H17: =F17*$A$5 -> 0 | I17: =G17*$D$5 -> 0 | J17: =B17*$G$5 -> 0 | K17: =E17+F17+G17+H17+I17+J17 -> 0 | L17: =D17-K17 -> 0 | M17: =IF(D17=0,"-",L17/D17) -> - | N17: =IF(D17=0,"-",E17/D17) -> - | O17: =IF((F17+G17)=0,"-",D17/(F17+G17)) -> - | P17: =P16+L17 -> 0
A18: 46245 | B18: 0 | C18: 0 | D18: =B18-C18 -> 0 | E18: 0 | F18: 0 | G18: 0 | H18: =F18*$A$5 -> 0 | I18: =G18*$D$5 -> 0 | J18: =B18*$G$5 -> 0 | K18: =E18+F18+G18+H18+I18+J18 -> 0 | L18: =D18-K18 -> 0 | M18: =IF(D18=0,"-",L18/D18) -> - | N18: =IF(D18=0,"-",E18/D18) -> - | O18: =IF((F18+G18)=0,"-",D18/(F18+G18)) -> - | P18: =P17+L18 -> 0
A19: 46246 | B19: 0 | C19: 0 | D19: =B19-C19 -> 0 | E19: 0 | F19: 0 | G19: 0 | H19: =F19*$A$5 -> 0 | I19: =G19*$D$5 -> 0 | J19: =B19*$G$5 -> 0 | K19: =E19+F19+G19+H19+I19+J19 -> 0 | L19: =D19-K19 -> 0 | M19: =IF(D19=0,"-",L19/D19) -> - | N19: =IF(D19=0,"-",E19/D19) -> - | O19: =IF((F19+G19)=0,"-",D19/(F19+G19)) -> - | P19: =P18+L19 -> 0
A20: 46247 | B20: 0 | C20: 0 | D20: =B20-C20 -> 0 | E20: 0 | F20: 0 | G20: 0 | H20: =F20*$A$5 -> 0 | I20: =G20*$D$5 -> 0 | J20: =B20*$G$5 -> 0 | K20: =E20+F20+G20+H20+I20+J20 -> 0 | L20: =D20-K20 -> 0 | M20: =IF(D20=0,"-",L20/D20) -> - | N20: =IF(D20=0,"-",E20/D20) -> - | O20: =IF((F20+G20)=0,"-",D20/(F20+G20)) -> - | P20: =P19+L20 -> 0
... A38: 46265 | B38: 0 | C38: 0 | D38: =B38-C38 -> 0 | E38: 0 | F38: 0 | G38: 0 | H38: =F38*$A$5 -> 0 | I38: =G38*$D$5 -> 0 | J38: =B38*$G$5 -> 0 | K38: =E38+F38+G38+H38+I38+J38 -> 0 | L38: =D38-K38 -> 0 | M38: =IF(D38=0,"-",L38/D38) -> - | N38: =IF(D38=0,"-",E38/D38) -> - | O38: =IF((F38+G38)=0,"-",D38/(F38+G38)) -> - | P38: =P37+L38 -> 0
A39: TOTAL | B39: =SUM(B8:B38) -> 0 | C39: =SUM(C8:C38) -> 0 | D39: =SUM(D8:D38) -> 0 | E39: =SUM(E8:E38) -> 0 | F39: =SUM(F8:F38) -> 0 | G39: =SUM(G8:G38) -> 0 | H39: =SUM(H8:H38) -> 0 | I39: =SUM(I8:I38) -> 0 | ... L39: =SUM(L8:L38) -> 0 | M39: =IF(D39=0,"-",L39/D39) -> - | N39: =IF(D39=0,"-",E39/D39) -> - | O39: =IF((F39+G39)=0,"-",D39/(F39+G39)) -> - | P39: =L39 -> 0
A41: 🔵 Blue = enter manually | ⬜ White/Grey = auto-calculated | 🟡 Yellow = editable fee % | 🟢 Green = positive | 🟡 Amber = 0–15% margin | 🔴 Red = negative

Sheet September
A2: 📊 Profit & Loss — September 2026 | N2: ="Currency: "&'⚙ Settings'!C6 -> Currency: €
A4: Agency Fee — Facebook | D4: Agency Fee — Google | G4: Transaction Fee | J4: 💡 Edit the coloured % cells above to update all fee calculations for this month automatically
A5: 0.06 | D5: 0.1 | G5: 0.05
A7: Date | B7: Gross Revenue | C7: Refunds | D7: Net Revenue | E7: Cost of Goods | F7: Adspend Facebook | G7: Adspend Google | H7: Agency Fee FB | I7: Agency Fee Google | J7: Transaction Fee | K7: Total Costs | L7: Profit | M7: Profit Margin % | N7: COG Impact % | O7: ROAS | P7: Cumulative Profit | Q7: Notes
A8: 46266 | B8: 0 | C8: 0 | D8: =B8-C8 -> 0 | E8: 0 | F8: 0 | G8: 0 | H8: =F8*$A$5 -> 0 | I8: =G8*$D$5 -> 0 | J8: =B8*$G$5 -> 0 | K8: =E8+F8+G8+H8+I8+J8 -> 0 | L8: =D8-K8 -> 0 | M8: =IF(D8=0,"-",L8/D8) -> - | N8: =IF(D8=0,"-",E8/D8) -> - | O8: =IF((F8+G8)=0,"-",D8/(F8+G8)) -> - | P8: =L8 -> 0
A9: 46267 | B9: 0 | C9: 0 | D9: =B9-C9 -> 0 | E9: 0 | F9: 0 | G9: 0 | H9: =F9*$A$5 -> 0 | I9: =G9*$D$5 -> 0 | J9: =B9*$G$5 -> 0 | K9: =E9+F9+G9+H9+I9+J9 -> 0 | L9: =D9-K9 -> 0 | M9: =IF(D9=0,"-",L9/D9) -> - | N9: =IF(D9=0,"-",E9/D9) -> - | O9: =IF((F9+G9)=0,"-",D9/(F9+G9)) -> - | P9: =P8+L9 -> 0
A10: 46268 | B10: 0 | C10: 0 | D10: =B10-C10 -> 0 | E10: 0 | F10: 0 | G10: 0 | H10: =F10*$A$5 -> 0 | I10: =G10*$D$5 -> 0 | J10: =B10*$G$5 -> 0 | K10: =E10+F10+G10+H10+I10+J10 -> 0 | L10: =D10-K10 -> 0 | M10: =IF(D10=0,"-",L10/D10) -> - | N10: =IF(D10=0,"-",E10/D10) -> - | O10: =IF((F10+G10)=0,"-",D10/(F10+G10)) -> - | P10: =P9+L10 -> 0
A11: 46269 | B11: 0 | C11: 0 | D11: =B11-C11 -> 0 | E11: 0 | F11: 0 | G11: 0 | H11: =F11*$A$5 -> 0 | I11: =G11*$D$5 -> 0 | J11: =B11*$G$5 -> 0 | K11: =E11+F11+G11+H11+I11+J11 -> 0 | L11: =D11-K11 -> 0 | M11: =IF(D11=0,"-",L11/D11) -> - | N11: =IF(D11=0,"-",E11/D11) -> - | O11: =IF((F11+G11)=0,"-",D11/(F11+G11)) -> - | P11: =P10+L11 -> 0
A12: 46270 | B12: 0 | C12: 0 | D12: =B12-C12 -> 0 | E12: 0 | F12: 0 | G12: 0 | H12: =F12*$A$5 -> 0 | I12: =G12*$D$5 -> 0 | J12: =B12*$G$5 -> 0 | K12: =E12+F12+G12+H12+I12+J12 -> 0 | L12: =D12-K12 -> 0 | M12: =IF(D12=0,"-",L12/D12) -> - | N12: =IF(D12=0,"-",E12/D12) -> - | O12: =IF((F12+G12)=0,"-",D12/(F12+G12)) -> - | P12: =P11+L12 -> 0
A13: 46271 | B13: 0 | C13: 0 | D13: =B13-C13 -> 0 | E13: 0 | F13: 0 | G13: 0 | H13: =F13*$A$5 -> 0 | I13: =G13*$D$5 -> 0 | J13: =B13*$G$5 -> 0 | K13: =E13+F13+G13+H13+I13+J13 -> 0 | L13: =D13-K13 -> 0 | M13: =IF(D13=0,"-",L13/D13) -> - | N13: =IF(D13=0,"-",E13/D13) -> - | O13: =IF((F13+G13)=0,"-",D13/(F13+G13)) -> - | P13: =P12+L13 -> 0
